Workbook

Sheet Main
B1: Site | C1: Period | D1: Dataset | E1: x | F1: y | G1: IGBP_site | H1: Climate_site | I1: Climate_KG0p01 | J1: Climate_l1 | K1: Crop type | L1: Irrigation
A2: 0 | B2: AR-TF1 | C2: 2016-2018 | D2: AMF | E2: -66.7335 | F2: -54.9733 | G2: =VLOOKUP(B2,AMF!$A$2:$G$691,7,FALSE) -> WET | H2: =VLOOKUP(B2,AMF!$A$2:$I$691,9,FALSE) -> 0 | I2: ET | J2: =LEFT(I2,1) -> E
A3: 1 | B3: CA-Cbo | C3: 1994-2020 | D3: AMF | E3: -79.9333 | F3: 44.3167 | G3: =VLOOKUP(B3,AMF!$A$2:$G$691,7,FALSE) -> DBF | H3: =VLOOKUP(B3,AMF!$A$2:$I$691,9,FALSE) -> Dfb | I3: Dfb | J3: =LEFT(I3,1) -> D
A4: 2 | B4: CA-DB2 | C4: 2019-2020 | D4: AMF | E4: -122.9951 | F4: 49.119 | G4: =VLOOKUP(B4,AMF!$A$2:$G$691,7,FALSE) -> WET | H4: =VLOOKUP(B4,AMF!$A$2:$I$691,9,FALSE) -> 0 | I4: Csb | J4: =LEFT(I4,1) -> C
A5: 3 | B5: CA-DBB | C5: 2014-2020 | D5: AMF | E5: -122.9849 | F5: 49.1293 | G5: =VLOOKUP(B5,AMF!$A$2:$G$691,7,FALSE) -> WET | H5: =VLOOKUP(B5,AMF!$A$2:$I$691,9,FALSE) -> Csb | I5: Csb | J5: =LEFT(I5,1) -> C
A6: 4 | B6: CA-ER1 | C6: 2015-2020 | D6: AMF | E6: -80.4123 | F6: 43.6405 | G6: =VLOOKUP(B6,AMF!$A$2:$G$691,7,FALSE) -> CRO | H6: =VLOOKUP(B6,AMF!$A$2:$I$691,9,FALSE) -> Dfb | I6: Dfb | J6: =LEFT(I6,1) -> D | K6: Corn
A7: 5 | B7: CA-LP1 | C7: 2007-2020 | D7: AMF | E7: -122.8414 | F7: 55.1119 | G7: =VLOOKUP(B7,AMF!$A$2:$G$691,7,FALSE) -> ENF | H7: =VLOOKUP(B7,AMF!$A$2:$I$691,9,FALSE) -> Csa | I7: Dfb | J7: =LEFT(I7,1) -> D
A8: 6 | B8: PE-QFR | C8: 2018-2019 | D8: AMF | E8: -73.319 | F8: -3.8344 | G8: =VLOOKUP(B8,AMF!$A$2:$G$691,7,FALSE) -> WET | H8: =VLOOKUP(B8,AMF!$A$2:$I$691,9,FALSE) -> Af | I8: Af | J8: =LEFT(I8,1) -> A
A9: 7 | B9: US-ALQ | C9: 2015-2021 | D9: AMF | E9: -89.6067 | F9: 46.0308 | G9: =VLOOKUP(B9,AMF!$A$2:$G$691,7,FALSE) -> WET | H9: =VLOOKUP(B9,AMF!$A$2:$I$691,9,FALSE) -> Dfb | I9: Dfb | J9: =LEFT(I9,1) -> D
A10: 8 | B10: US-ARM | C10: 2003-2020 | D10: AMF | E10: -97.4888 | F10: 36.6058 | G10: =VLOOKUP(B10,AMF!$A$2:$G$691,7,FALSE) -> CRO | H10: =VLOOKUP(B10,AMF!$A$2:$I$691,9,FALSE) -> Cfa | I10: Cfa | J10: =LEFT(I10,1) -> C | K10: winter wheat, corn, soy, alfalfa
A11: 9 | B11: US-Bar | C11: 2004-2021 | D11: AMF | E11: -71.2881 | F11: 44.0646 | G11: =VLOOKUP(B11,AMF!$A$2:$G$691,7,FALSE) -> DBF | H11: =VLOOKUP(B11,AMF!$A$2:$I$691,9,FALSE) -> Dfb | I11: Dfb | J11: =LEFT(I11,1) -> D
A12: 10 | B12: US-Bi1 | C12: 2016-2021 | D12: AMF | E12: -121.4993 | F12: 38.0992 | G12: =VLOOKUP(B12,AMF!$A$2:$G$691,7,FALSE) -> CRO | H12: =VLOOKUP(B12,AMF!$A$2:$I$691,9,FALSE) -> Csa | I12: Csa | J12: =LEFT(I12,1) -> C | K12: alfalfa
A13: 11 | B13: US-Bi2 | C13: 2017-2021 | D13: AMF | E13: -121.5351 | F13: 38.1091 | G13: =VLOOKUP(B13,AMF!$A$2:$G$691,7,FALSE) -> CRO | H13: =VLOOKUP(B13,AMF!$A$2:$I$691,9,FALSE) -> Csa | I13: Csa | J13: =LEFT(I13,1) -> C | K13: Corn
A14: 12 | B14: US-BRG | C14: 2016-2020 | D14: AMF | E14: -86.5406 | F14: 39.2167 | G14: =VLOOKUP(B14,AMF!$A$2:$G$691,7,FALSE) -> GRA | H14: =VLOOKUP(B14,AMF!$A$2:$I$691,9,FALSE) -> Cfa | I14: Dfa | J14: =LEFT(I14,1) -> D
A15: 13 | B15: US-BZB | C15: 2011-2021 | D15: AMF | E15: -148.3208 | F15: 64.6955 | G15: =VLOOKUP(B15,AMF!$A$2:$G$691,7,FALSE) -> WET | H15: =VLOOKUP(B15,AMF!$A$2:$I$691,9,FALSE) -> Dfd | I15: Dfb | J15: =LEFT(I15,1) -> D
A16: 14 | B16: US-BZF | C16: 2011-2021 | D16: AMF | E16: -148.3121 | F16: 64.7013 | G16: =VLOOKUP(B16,AMF!$A$2:$G$691,7,FALSE) -> WET | H16: =VLOOKUP(B16,AMF!$A$2:$I$691,9,FALSE) -> Dfd | I16: Dfb | J16: =LEFT(I16,1) -> D
A17: 15 | B17: US-BZo | C17: 2018-2021 | D17: AMF | E17: -148.33 | F17: 64.6936 | G17: =VLOOKUP(B17,AMF!$A$2:$G$691,7,FALSE) -> WET | H17: =VLOOKUP(B17,AMF!$A$2:$I$691,9,FALSE) -> Dfd | I17: Dfb | J17: =LEFT(I17,1) -> D
A18: 16 | B18: US-BZS | C18: 2010-2021 | D18: AMF | E18: -148.3235 | F18: 64.6963 | G18: =VLOOKUP(B18,AMF!$A$2:$G$691,7,FALSE) -> ENF | H18: =VLOOKUP(B18,AMF!$A$2:$I$691,9,FALSE) -> Dfd | I18: Dfb | J18: =LEFT(I18,1) -> D
A19: 17 | B19: US-CF1 | C19: 2017-2020 | D19: AMF | E19: -117.0821 | F19: 46.7815 | G19: =VLOOKUP(B19,AMF!$A$2:$G$691,7,FALSE) -> CRO | H19: =VLOOKUP(B19,AMF!$A$2:$I$691,9,FALSE) -> Dsb | I19: Dsb | J19: =LEFT(I19,1) -> D | K19: Wheat / Garbanzo | L19: None
A20: 18 | B20: US-CF2 | C20: 2017-2020 | D20: AMF | E20: -117.0908 | F20: 46.784 | G20: =VLOOKUP(B20,AMF!$A$2:$G$691,7,FALSE) -> CRO | H20: =VLOOKUP(B20,AMF!$A$2:$I$691,9,FALSE) -> Dsb | I20: Dsb | J20: =LEFT(I20,1) -> D | K20: Wheat / Garbanzo | L20: None
A21: 19 | B21: US-CF3 | C21: 2017-2021 | D21: AMF | E21: -117.1261 | F21: 46.7551 | G21: =VLOOKUP(B21,AMF!$A$2:$G$691,7,FALSE) -> CRO | H21: =VLOOKUP(B21,AMF!$A$2:$I$691,9,FALSE) -> Dsb | I21: Dsb | J21: =LEFT(I21,1) -> D | K21: Wheat / Garbanzo | L21: None
A22: 20 | B22: US-CF4 | C22: 2017-2021 | D22: AMF | E22: -117.1285 | F22: 46.7518 | G22: =VLOOKUP(B22,AMF!$A$2:$G$691,7,FALSE) -> CRO | H22: =VLOOKUP(B22,AMF!$A$2:$I$691,9,FALSE) -> Dsb | I22: Dsb | J22: =LEFT(I22,1) -> D | K22: Wheat / Garbanzo | L22: None
A23: 21 | B23: US-CS1 | C23: 2018-2019 | D23: AMF | E23: -89.5379 | F23: 44.1031 | G23: =VLOOKUP(B23,AMF!$A$2:$G$691,7,FALSE) -> CRO | H23: =VLOOKUP(B23,AMF!$A$2:$I$691,9,FALSE) -> Dfa | I23: Dfb | J23: =LEFT(I23,1) -> D | K23: Potato | L23: Center-Pivot
A24: 22 | B24: US-CS2 | C24: 2018-2021 | D24: AMF | E24: -89.5002 | F24: 44.1467 | G24: =VLOOKUP(B24,AMF!$A$2:$G$691,7,FALSE) -> ENF | H24: =VLOOKUP(B24,AMF!$A$2:$I$691,9,FALSE) -> Dfa | I24: Dfb | J24: =LEFT(I24,1) -> D
A25: 23 | B25: US-CS3 | C25: 2019-2020 | D25: AMF | E25: -89.5727 | F25: 44.1394 | G25: =VLOOKUP(B25,AMF!$A$2:$G$691,7,FALSE) -> CRO | H25: =VLOOKUP(B25,AMF!$A$2:$I$691,9,FALSE) -> Dfa | I25: Dfb | J25: =LEFT(I25,1) -> D | K25: Potato | L25: Center-Pivot
A26: 24 | B26: US-CS4 | C26: 2020-2021 | D26: AMF | E26: -89.5475 | F26: 44.1597 | G26: =VLOOKUP(B26,AMF!$A$2:$G$691,7,FALSE) -> CRO | H26: =VLOOKUP(B26,AMF!$A$2:$I$691,9,FALSE) -> Dfa | I26: Dfb | J26: =LEFT(I26,1) -> D | K26: Potato | L26: Center-Pivot
A27: 25 | B27: US-DFC | C27: 2018-2021 | D27: AMF | E27: -89.7117 | F27: 43.3448 | G27: =VLOOKUP(B27,AMF!$A$2:$G$691,7,FALSE) -> CRO | H27: =VLOOKUP(B27,AMF!$A$2:$I$691,9,FALSE) -> Dfb | I27: Dfa | J27: =LEFT(I27,1) -> D | K27: alfalfa, corn, soybean and wheat,
A28: 26 | B28: US-DS3 | C28: 2021-2021 | D28: AMF | E28: -121.549 | F28: 38.1235 | G28: =VLOOKUP(B28,AMF!$A$2:$G$691,7,FALSE) -> CRO | H28: =VLOOKUP(B28,AMF!$A$2:$I$691,9,FALSE) -> Csa | I28: Csa | J28: =LEFT(I28,1) -> C | K28: rice
A29: 27 | B29: US-EDN | C29: 2018-2019 | D29: AMF | E29: -122.114 | F29: 37.6156 | G29: =VLOOKUP(B29,AMF!$A$2:$G$691,7,FALSE) -> WET | H29: =VLOOKUP(B29,AMF!$A$2:$I$691,9,FALSE) -> Csa | I29: Csb | J29: =LEFT(I29,1) -> C
A30: 28 | B30: US-EML | C30: 2008-2020 | D30: AMF | E30: -149.2536 | F30: 63.8784 | G30: =VLOOKUP(B30,AMF!$A$2:$G$691,7,FALSE) -> OSH | H30: =VLOOKUP(B30,AMF!$A$2:$I$691,9,FALSE) -> ET | I30: Dfc | J30: =LEFT(I30,1) -> D
A31: 29 | B31: US-GLE | C31: 2005-2020 | D31: AMF | E31: -106.2399 | F31: 41.3665 | G31: =VLOOKUP(B31,AMF!$A$2:$G$691,7,FALSE) -> ENF | H31: =VLOOKUP(B31,AMF!$A$2:$I$691,9,FALSE) -> Dfc | I31: Dfc | J31: =LEFT(I31,1) -> D
A32: 30 | B32: US-Ha1 | C32: 1991-2020 | D32: AMF | E32: -72.1715 | F32: 42.5378 | G32: =VLOOKUP(B32,AMF!$A$2:$G$691,7,FALSE) -> DBF | H32: =VLOOKUP(B32,AMF!$A$2:$I$691,9,FALSE) -> Dfb | I32: Dfb | J32: =LEFT(I32,1) -> D
A33: 31 | B33: US-HB1 | C33: 2019-2019 | D33: AMF | E33: -79.1957 | F33: 33.3455 | G33: =VLOOKUP(B33,AMF!$A$2:$G$691,7,FALSE) -> WET | H33: =VLOOKUP(B33,AMF!$A$2:$I$691,9,FALSE) -> Cfa | I33: Cfa | J33: =LEFT(I33,1) -> C
A34: 32 | B34: US-HB2 | C34: 2019-2019 | D34: AMF | E34: -79.244 | F34: 33.3242 | G34: =VLOOKUP(B34,AMF!$A$2:$G$691,7,FALSE) -> ENF | H34: =VLOOKUP(B34,AMF!$A$2:$I$691,9,FALSE) -> Cfa | I34: Cfa | J34: =LEFT(I34,1) -> C
A35: 33 | B35: US-HB3 | C35: 2019-2021 | D35: AMF | E35: -79.2322 | F35: 33.3482 | G35: =VLOOKUP(B35,AMF!$A$2:$G$691,7,FALSE) -> ENF | H35: =VLOOKUP(B35,AMF!$A$2:$I$691,9,FALSE) -> Cfa | I35: Cfa | J35: =LEFT(I35,1) -> C
A36: 34 | B36: US-Hn2 | C36: 2015-2018 | D36: AMF | E36: -119.4641 | F36: 46.6889 | G36: =VLOOKUP(B36,AMF!$A$2:$G$691,7,FALSE) -> GRA | H36: =VLOOKUP(B36,AMF!$A$2:$I$691,9,FALSE) -> Bsk | I36: BWk | J36: =LEFT(I36,1) -> B
A37: 35 | B37: US-Hn3 | C37: 2017-2018 | D37: AMF | E37: -119.4614 | F37: 46.6878 | G37: =VLOOKUP(B37,AMF!$A$2:$G$691,7,FALSE) -> OSH | H37: =VLOOKUP(B37,AMF!$A$2:$I$691,9,FALSE) -> Bsk | I37: BWk | J37: =LEFT(I37,1) -> B
A38: 36 | B38: US-Ho2 | C38: 1999-2020 | D38: AMF | E38: -68.747 | F38: 45.2091 | G38: =VLOOKUP(B38,AMF!$A$2:$G$691,7,FALSE) -> ENF | H38: =VLOOKUP(B38,AMF!$A$2:$I$691,9,FALSE) -> Dfb | I38: Dfb | J38: =LEFT(I38,1) -> D
A39: 37 | B39: US-HWB | C39: 2015-2018 | D39: AMF | E39: -77.8488 | F39: 40.8608 | G39: =VLOOKUP(B39,AMF!$A$2:$G$691,7,FALSE) -> CVM | H39: =VLOOKUP(B39,AMF!$A$2:$I$691,9,FALSE) -> Dfb | I39: Dfa | J39: =LEFT(I39,1) -> D
A40: 38 | B40: US-ICh | C40: 2007-2021 | D40: AMF | E40: -149.2958 | F40: 68.6068 | G40: =VLOOKUP(B40,AMF!$A$2:$G$691,7,FALSE) -> OSH | H40: =VLOOKUP(B40,AMF!$A$2:$I$691,9,FALSE) -> ET | I40: Dfc | J40: =LEFT(I40,1) -> D
...

Sheet Koppen-Geiger
A1: field_1 | B1: Site | C1: Period | D1: Dataset | E1: x | F1: y | G1: KG1 | H1: Class | K1: Code | L1: Class
A2: 0 | B2: AR-TF1 | C2: 2016-2018 | D2: AMF | E2: -66.7335 | F2: -54.9733 | G2: 29 | H2: =VLOOKUP(G2,$K$2:$L$31,2) -> ET | K2: 1 | L2: Af | M2: Tropical, rainforest | N2: [0 0 255]
A3: 1 | B3: CA-Cbo | C3: 1994-2020 | D3: AMF | E3: -79.9333 | F3: 44.3167 | G3: 26 | H3: =VLOOKUP(G3,$K$2:$L$31,2) -> Dfb | K3: 2 | L3: Am | M3: Tropical, monsoon | N3: [0 120 255]
A4: 2 | B4: CA-DB2 | C4: 2019-2020 | D4: AMF | E4: -122.9951 | F4: 49.119 | G4: 9 | H4: =VLOOKUP(G4,$K$2:$L$31,2) -> Csb | K4: 3 | L4: Aw | M4: Tropical, savannah | N4: [70 170 250]
A5: 3 | B5: CA-DBB | C5: 2014-2020 | D5: AMF | E5: -122.9849 | F5: 49.1293 | G5: 9 | H5: =VLOOKUP(G5,$K$2:$L$31,2) -> Csb | K5: 4 | L5: BWh | M5: Arid, desert, hot | N5: [255 0 0]
A6: 4 | B6: CA-ER1 | C6: 2015-2020 | D6: AMF | E6: -80.4123 | F6: 43.6405 | G6: 26 | H6: =VLOOKUP(G6,$K$2:$L$31,2) -> Dfb | K6: 5 | L6: BWk | M6: Arid, desert, cold | N6: [255 150 150]
A7: 5 | B7: CA-LP1 | C7: 2007-2020 | D7: AMF | E7: -122.8414 | F7: 55.1119 | G7: 26 | H7: =VLOOKUP(G7,$K$2:$L$31,2) -> Dfb | K7: 6 | L7: BSh | M7: Arid, steppe, hot | N7: [245 165 0]
A8: 6 | B8: PE-QFR | C8: 2018-2019 | D8: AMF | E8: -73.319 | F8: -3.8344 | G8: 1 | H8: =VLOOKUP(G8,$K$2:$L$31,2) -> Af | K8: 7 | L8: BSk | M8: Arid, steppe, cold | N8: [255 220 100]
A9: 7 | B9: US-ALQ | C9: 2015-2021 | D9: AMF | E9: -89.6067 | F9: 46.0308 | G9: 26 | H9: =VLOOKUP(G9,$K$2:$L$31,2) -> Dfb | K9: 8 | L9: Csa | M9: Temperate, dry summer, hot summer | N9: [255 255 0]
A10: 8 | B10: US-ARM | C10: 2003-2020 | D10: AMF | E10: -97.4888 | F10: 36.6058 | G10: 14 | H10: =VLOOKUP(G10,$K$2:$L$31,2) -> Cfa | K10: 9 | L10: Csb | M10: Temperate, dry summer, warm summer | N10: [200 200 0]
A11: 9 | B11: US-Bar | C11: 2004-2021 | D11: AMF | E11: -71.2881 | F11: 44.0646 | G11: 26 | H11: =VLOOKUP(G11,$K$2:$L$31,2) -> Dfb | K11: 10 | L11: Csc | M11: Temperate, dry summer, cold summer | N11: [150 150 0]
A12: 10 | B12: US-Bi1 | C12: 2016-2021 | D12: AMF | E12: -121.4993 | F12: 38.0992 | G12: 8 | H12: =VLOOKUP(G12,$K$2:$L$31,2) -> Csa | K12: 11 | L12: Cwa | M12: Temperate, dry winter, hot summer | N12: [150 255 150]
A13: 11 | B13: US-Bi2 | C13: 2017-2021 | D13: AMF | E13: -121.5351 | F13: 38.1091 | G13: 8 | H13: =VLOOKUP(G13,$K$2:$L$31,2) -> Csa | K13: 12 | L13: Cwb | M13: Temperate, dry winter, warm summer | N13: [100 200 100]
... A31: 29 | B31: US-GLE | C31: 2005-2020 | D31: AMF | E31: -106.2399 | F31: 41.3665 | G31: 27 | H31: =VLOOKUP(G31,$K$2:$L$31,2) -> Dfc | K31: 30 | L31: EF | M31: Polar, frost | N31: [102 102 102]
A32: 30 | B32: US-Ha1 | C32: 1991-2020 | D32: AMF | E32: -72.1715 | F32: 42.5378 | G32: 26 | H32: =VLOOKUP(G32,$K$2:$L$31,2) -> Dfb
A33: 31 | B33: US-HB1 | C33: 2019-2019 | D33: AMF | E33: -79.1957 | F33: 33.3455 | G33: 14 | H33: =VLOOKUP(G33,$K$2:$L$31,2) -> Cfa
A34: 32 | B34: US-HB2 | C34: 2019-2019 | D34: AMF | E34: -79.244 | F34: 33.3242 | G34: 14 | H34: =VLOOKUP(G34,$K$2:$L$31,2) -> Cfa
A35: 33 | B35: US-HB3 | C35: 2019-2021 | D35: AMF | E35: -79.2322 | F35: 33.3482 | G35: 14 | H35: =VLOOKUP(G35,$K$2:$L$31,2) -> Cfa
A36: 34 | B36: US-Hn2 | C36: 2015-2018 | D36: AMF | E36: -119.4641 | F36: 46.6889 | G36: 5 | H36: =VLOOKUP(G36,$K$2:$L$31,2) -> BWk
A37: 35 | B37: US-Hn3 | C37: 2017-2018 | D37: AMF | E37: -119.4614 | F37: 46.6878 | G37: 5 | H37: =VLOOKUP(G37,$K$2:$L$31,2) -> BWk
A38: 36 | B38: US-Ho2 | C38: 1999-2020 | D38: AMF | E38: -68.747 | F38: 45.2091 | G38: 26 | H38: =VLOOKUP(G38,$K$2:$L$31,2) -> Dfb
A39: 37 | B39: US-HWB | C39: 2015-2018 | D39: AMF | E39: -77.8488 | F39: 40.8608 | G39: 25 | H39: =VLOOKUP(G39,$K$2:$L$31,2) -> Dfa
A40: 38 | B40: US-ICh | C40: 2007-2021 | D40: AMF | E40: -149.2958 | F40: 68.6068 | G40: 27 | H40: =VLOOKUP(G40,$K$2:$L$31,2) -> Dfc
A41: 39 | B41: US-ICs | C41: 2007-2020 | D41: AMF | E41: -149.311 | F41: 68.6058 | G41: 27 | H41: =VLOOKUP(G41,$K$2:$L$31,2) -> Dfc
A42: 40 | B42: US-ICt | C42: 2007-2021 | D42: AMF | E42: -149.3041 | F42: 68.6063 | G42: 27 | H42: =VLOOKUP(G42,$K$2:$L$31,2) -> Dfc
A43: 41 | B43: US-Jo1 | C43: 2010-2020 | D43: AMF | E43: -106.635 | F43: 32.582 | G43: 5 | H43: =VLOOKUP(G43,$K$2:$L$31,2) -> BWk
... A273: 271 | B273: SE-Svb | C273: 2014-2020 | D273: ICOS-WW | E273: 19.776502 | F273: 64.256305 | G273: 27 | H273: =VLOOKUP(G273,$K$2:$L$31,2) -> Dfc

Sheet 272 sites
A1: This list includes all the sites with data from 2018 onwards from AMF, ICOS-WW, ICOS-Drought, OzFlux
B2: Site | C2: Period | D2: Dataset | E2: x | F2: y | G2: ICOS-both datasets | H2: Downloaded
A3: 0 | B3: AR-TF1 | C3: 2016-2018 | D3: AMF | E3: -66.7335 | F3: -54.9733
A4: 1 | B4: CA-Cbo | C4: 1994-2020 | D4: AMF | E4: -79.9333 | F4: 44.3167
A5: 2 | B5: CA-DB2 | C5: 2019-2020 | D5: AMF | E5: -122.9951 | F5: 49.119
A6: 3 | B6: CA-DBB | C6: 2014-2020 | D6: AMF | E6: -122.9849 | F6: 49.1293
A7: 4 | B7: CA-ER1 | C7: 2015-2020 | D7: AMF | E7: -80.4123 | F7: 43.6405
A8: 5 | B8: CA-LP1 | C8: 2007-2020 | D8: AMF | E8: -122.8414 | F8: 55.1119
A9: 6 | B9: PE-QFR | C9: 2018-2019 | D9: AMF | E9: -73.319 | F9: -3.8344
A10: 7 | B10: US-ALQ | C10: 2015-2021 | D10: AMF | E10: -89.6067 | F10: 46.0308
A11: 8 | B11: US-ARM | C11: 2003-2020 | D11: AMF | E11: -97.4888 | F11: 36.6058
A12: 9 | B12: US-Bar | C12: 2004-2021 | D12: AMF | E12: -71.2881 | F12: 44.0646
A13: 10 | B13: US-Bi1 | C13: 2016-2021 | D13: AMF | E13: -121.4993 | F13: 38.0992
A14: 11 | B14: US-Bi2 | C14: 2017-2021 | D14: AMF | E14: -121.5351 | F14: 38.1091
... A149: 146 | B149: AU-Wom | C149: 2010-2021 | D149: OzFlux | E149: 144.0944 | F149: -37.4222
A150: 147 | B150: BE-Bra | C150: 1996-2018 | D150: ICOS-Drought | E150: 4.520098 | F150: 51.30701 | G150: x
A151: 148 | B151: BE-Lon | C151: 2004-2018 | D151: ICOS-Drought | E151: 4.746202 | F151: 50.551338
A152: 149 | B152: BE-Vie | C152: 1996-2018 | D152: ICOS-Drought | E152: 5.99871 | F152: 50.306918 | G152: x
A153: 150 | B153: CH-Aws | C153: 2010-2018 | D153: ICOS-Drought | E153: 9.790417 | F153: 46.583306 | G153: x
A154: 151 | B154: CH-Cha | C154: 2005-2018 | D154: ICOS-Drought | E154: 8.41044 | F154: 47.21022 | G154: x
A155: 152 | B155: CH-Dav | C155: 1997-2018 | D155: ICOS-Drought | E155: 9.85591 | F155: 46.81533 | G155: x
A156: 153 | B156: CH-Fru | C156: 2005-2018 | D156: ICOS-Drought | E156: 8.53778 | F156: 47.11583 | G156: x
A157: 154 | B157: CH-Lae | C157: 2004-2018 | D157: ICOS-Drought | E157: 8.365 | F157: 47.47808 | G157: x
A158: 155 | B158: CH-Oe2 | C158: 2004-2018 | D158: ICOS-Drought | E158: 7.73433 | F158: 47.28631 | G158: x
A159: 156 | B159: CZ-BK1 | C159: 2004-2018 | D159: ICOS-Drought | E159: 18.536882 | F159: 49.502075 | G159: x
A160: 157 | B160: CZ-Lnz | C160: 2015-2018 | D160: ICOS-Drought | E160: 16.946331 | F160: 48.68155 | G160: x
A161: 158 | B161: CZ-RAJ | C161: 2012-2018 | D161: ICOS-Drought | E161: 16.696513 | F161: 49.443724 | G161: x
A162: 159 | B162: CZ-Stn | C162: 2010-2018 | D162: ICOS-Drought | E162: 17.9699 | F162: 49.035975 | G162: x
A163: 160 | B163: CZ-wet | C163: 2006-2018 | D163: ICOS-Drought | E163: 14.77035 | F163: 49.02465 | G163: x
... A168: 165 | B168: DE-HoH | C168: 2015-2018 | D168: ICOS-Drought | E168: 11.221911 | F168: 52.08637 | G168: x
A169: 166 | B169: DE-Hte | C169: 2009-2018 | D169: ICOS-Drought | E169: 12.176111 | F169: 54.210278
A170: 167 | B170: DE-Hzd | C170: 2010-2018 | D170: ICOS-Drought | E170: 13.48978 | F170: 50.96381 | G170: x
A171: 168 | B171: DE-Kli | C171: 2004-2018 | D171: ICOS-Drought | E171: 13.52238 | F171: 50.89306 | G171: x
A172: 169 | B172: DE-Obe | C172: 2008-2018 | D172: ICOS-Drought | E172: 13.72129 | F172: 50.78666 | G172: x
A173: 170 | B173: DE-RuR | C173: 2011-2018 | D173: ICOS-Drought | E173: 6.304126 | F173: 50.621914 | G173: x
A174: 171 | B174: DE-RuS | C174: 2011-2018 | D174: ICOS-Drought | E174: 6.447076 | F174: 50.866033 | G174: x
A175: 172 | B175: DE-RuW | C175: 2010-2018 | D175: ICOS-Drought | E175: 6.3309627 | F175: 50.50493 | G175: x
A176: 173 | B176: DE-Tha | C176: 1996-2018 | D176: ICOS-Drought | E176: 13.56515 | F176: 50.96256 | G176: x
A177: 174 | B177: DK-Sor | C177: 1996-2018 | D177: ICOS-Drought | E177: 11.645207 | F177: 55.486286 | G177: x
A178: 175 | B178: ES-Abr | C178: 2015-2018 | D178: ICOS-Drought | E178: -6.785881 | F178: 38.701839 | G178: x
...

Sheet AMF
A1: Site ID | B1: Name | C1: Principal Investigator | D1: Data Use Policy | E1: AmeriFlux BASE Data | F1: AmeriFlux FLUXNET Data | G1: Vegetation Abbreviation (IGBP) | H1: Vegetation Description (IGBP) | I1: Climate Class Abbreviation (Koeppen) | J1: Climate Class Description (Koeppen) | K1: Mean Average Precipitation (mm) | L1: Mean Average Temperature (degrees C) | M1: Country | N1: Latitude (degrees) | O1: Longitude (degrees) | P1: Elevation (m) | Q1: Number of years of AmeriFlux BASE data | R1: AmeriFlux BASE Data Start | S1: AmeriFlux BASE Data End | T1: Years of AmeriFlux BASE Data | U1: AmeriFlux BASE DOI | V1: AmeriFlux FLUXNET Data Start | W1: AmeriFlux FLUXNET Data End | X1: Years of AmeriFlux FLUXNET Data | Y1: AmeriFlux FLUXNET DOI | Z1: Site Start | AA1: Site End | AB1: BASE variables available | AC1: FLUXNET variables available
A2: AR-Bal | B2: Balcarce BA | C2: Natalia Edith Tonti (ntonti@at.fcen.uba.ar) | D2: CC-BY-4.0 | E2: Yes | F2: No | G2: CRO | H2: Croplands: Lands covered with temporary crops followed by harvest and a bare soil period (e.g., single and multiple cropping systems). Note that perennial woody crops will be classified as the appropriate forest or shrub land cover type. | I2: Cfb | J2: Marine West Coast: mild with no dry season, warm summer | K2: 926 | L2: 14 | M2: Argentina | N2: -37.7596 | O2: -58.3024 | P2: 130 | Q2: 2 | R2: 2012 | S2: 2013 | T2: 2012, 2013 | U2: https://doi.org/10.17190/AMF/2315764 | Z2: 2012 | AA2: 2013 | AB2: CO2, CO2_SIGMA, FC, FC_SSITC_TEST, G, H, H2O, H2O_SIGMA, H_SSITC_TEST, LE, LE_SSITC_TEST, MO_LENGTH, NEE, P, PA, PPFD_IN, RH, SW_IN, TA, TAU_SSITC_TEST, TS, T_SONIC, T_SONIC_SIGMA, U_SIGMA, USTAR, V_SIGMA, WD, WS, W_SIGMA, ZL
A3: AR-CCa | B3: Carlos Casares agriculture | C3: Gabriela Posse (posse.gabriela@gmail.com) | D3: CC-BY-4.0 | E3: Yes | F3: No | G3: CRO | H3: Croplands: Lands covered with temporary crops followed by harvest and a bare soil period (e.g., single and multiple cropping systems). Note that perennial woody crops will be classified as the appropriate forest or shrub land cover type. | I3: Cfa | J3: Humid Subtropical: mild with no dry season, hot summer | K3: 1060 | L3: 16.1 | M3: Argentina | N3: -35.621 | O3: -61.3181 | P3: 83 | Q3: 9 | R3: 2012 | S3: 2020 | T3: 2012, 2013, 2014, 2015, 2016, 2017, 2018, 2019, 2020 | U3: https://doi.org/10.17190/AMF/1880910 | Z3: 2012 | AB3: CO2, CO2_MIXING_RATIO, CO2_SIGMA, FC, FETCH_70, FETCH_80, FETCH_90, FETCH_MAX, H, H2O, H2O_MIXING_RATIO, H2O_SIGMA, LE, MO_LENGTH, PA, PPFD_IN, RH, TA, TAU, T_SONIC, T_SONIC_SIGMA, U_SIGMA, USTAR, VPD, V_SIGMA, WD, WS, W_SIGMA, WS_MAX, ZL
A4: AR-CCg | B4: Carlos Casares grassland | C4: Gabriela Posse (posse.gabriela@gmail.com) | D4: CC-BY-4.0 | E4: Yes | F4: Yes | G4: GRA | H4: Grasslands: Lands with herbaceous types of cover. Tree and shrub cover is less than 10%. Permanent wetlands lands with a permanent mixture of water and herbaceous or woody vegetation. The vegetation can be present in either salt, brackish, or fresh water. | I4: Cfa | J4: Humid Subtropical: mild with no dry season, hot summer | K4: 1060 | L4: 16.1 | M4: Argentina | N4: -35.9244 | O4: -61.1855 | P4: 84 | Q4: 6 | R4: 2018 | S4: 2023 | T4: 2018, 2019, 2020, 2021, 2022, 2023 | U4: https://doi.org/10.17190/AMF/1865474 | V4: 2018 | W4: 2023 | X4: 2018, 2019, 2020, 2021, 2022, 2023 | Y4: https://doi.org/10.17190/AMF/2469434 | Z4: 2018 | AB4: CO2, CO2_MIXING_RATIO, CO2_SIGMA, FC, FETCH_70, FETCH_80, FETCH_90, FETCH_MAX, H, H2O, H2O_MIXING_RATIO, H2O_SIGMA, LE, MO_LENGTH, PA, PPFD_IN, RH, TA, TAU, T_SONIC, T_SONIC_SIGMA, U_SIGMA, USTAR, VPD, V_SIGMA, WD, WS, W_SIGMA, WS_MAX, ZL
A5: AR-Cel | B5: CELPA Mar Chiquita BA | C5: Paulina Martinetto (pmartin@mdp.edu.ar) | D5: Legacy | E5: Yes | F5: No | G5: WET | H5: Permanent Wetlands: Lands with a permanent mixture of water and herbaceous or woody vegetation that cover extensive areas. The vegetation can be present in either salt, brackish, or fresh water | I5: Cfb | J5: Marine West Coast: mild with no dry season, warm summer | K5: 926 | L5: 14 | M5: Argentina | N5: -37.7028 | O5: -57.4192 | P5: 1 | Q5: 1 | R5: 2018 | S5: 2018 | T5: 2018 | U5: https://doi.org/10.17190/AMF/2204054 | Z5: 2018 | AA5: 2018 | AB5: CO2, CO2_SIGMA, FC, FC_SSITC_TEST, G, H, H2O, H2O_SIGMA, H_SSITC_TEST, LE, LE_SSITC_TEST, MO_LENGTH, NEE, P, PA, PPFD_IN, RH, SC, SWC, SW_IN, TA, TAU_SSITC_TEST, TS, T_SONIC, T_SONIC_SIGMA, U_SIGMA, USTAR, V_SIGMA, WD, WS, W_SIGMA, ZL
A6: AR-Rom | B6: Romano Mar Chiquita BA | C6: Natalia Edith Tonti (ntonti@at.fcen.uba.ar) | D6: Legacy | E6: Yes | F6: No | G6: WET | H6: Permanent Wetlands: Lands with a permanent mixture of water and herbaceous or woody vegetation that cover extensive areas. The vegetation can be present in either salt, brackish, or fresh water | I6: Cfb | J6: Marine West Coast: mild with no dry season, warm summer | K6: 926 | L6: 14 | M6: Argentina | N6: -37.5508 | O6: -57.2972 | P6: 1 | Q6: 2 | R6: 2014 | S6: 2015 | T6: 2014, 2015 | U6: https://doi.org/10.17190/AMF/2315765 | Z6: 2014 | AA6: 2015 | AB6: CO2, CO2_SIGMA, FC, FC_SSITC_TEST, G, H, H2O, H2O_SIGMA, H_SSITC_TEST, LE, LE_SSITC_TEST, MO_LENGTH, NEE, P, PA, PPFD_IN, RH, SW_IN, TA, TAU_SSITC_TEST, TS, T_SONIC, T_SONIC_SIGMA, U_SIGMA, USTAR, V_SIGMA, WD, WS, W_SIGMA, ZL
A7: AR-TF1 | B7: Rio Moat bog | C7: Veronica Pancotto (pancotto@cadic-conicet.gob.ar) | D7: CC-BY-4.0 | E7: Yes | F7: Yes | G7: WET | H7: Permanent Wetlands: Lands with a permanent mixture of water and herbaceous or woody vegetation that cover extensive areas. The vegetation can be present in either salt, brackish, or fresh water | M7: Argentina | N7: -54.9733 | O7: -66.7335 | P7: 40 | Q7: 3 | R7: 2016 | S7: 2018 | T7: 2016, 2017, 2018 | U7: https://doi.org/10.17190/AMF/1543389 | V7: 2016 | W7: 2018 | X7: 2016, 2017, 2018 | Y7: https://doi.org/10.17190/AMF/1818370 | Z7: 2016 | AA7: 2018 | AB7: CO2, FC, FC_SSITC_TEST, H, H_SSITC_TEST, LE, LE_SSITC_TEST, PA, PPFD_IN, RH, SW_IN, TA, USTAR, WD, WS
A8: AR-TF2 | B8: Rio Pipo bog | C8: Veronica Pancotto (pancotto@cadic-conicet.gob.ar) | D8: CC-BY-4.0 | E8: Yes | F8: No | G8: WET | H8: Permanent Wetlands: Lands with a permanent mixture of water and herbaceous or woody vegetation that cover extensive areas. The vegetation can be present in either salt, brackish, or fresh water | K8: 530 | L8: 5.5 | M8: Argentina | N8: -54.8269 | O8: -68.4549 | P8: 60 | Q8: 3 | R8: 2016 | S8: 2018 | T8: 2016, 2017, 2018 | U8: https://doi.org/10.17190/AMF/1543388 | Z8: 2016 | AA8: 2018 | AB8: FC, FC_SSITC_TEST, H, H_SSITC_TEST, LE, LE_SSITC_TEST, PPFD_IN, RH, SW_IN, TA, USTAR, WD, WS
A9: BR-BNT | B9: BIONTE | C9: Robinson Negron-Juarez (robinson.inj@lbl.gov) | D9: Legacy | E9: No | F9: No | G9: EBF | H9: Evergreen Broadleaf Forests: Lands dominated by woody vegetation with a percent cover >60% and height exceeding 2 meters. Almost all trees and shrubs remain green year round. Canopy is never without green foliage. | K9: 2300 | L9: 27.4 | M9: Brazil | N9: -2.6334 | O9: -60.1505 | P9: 116 | Q9: 0 | Z9: 2023
A10: BR-Cax | B10: CAX, FLONA Caxiuanã micromet tower | C10: Alessandro Araujo (alessandro.araujo@embrapa.br) | D10: CC-BY-4.0 | E10: No | F10: No | G10: EBF | H10: Evergreen Broadleaf Forests: Lands dominated by woody vegetation with a percent cover >60% and height exceeding 2 meters. Almost all trees and shrubs remain green year round. Canopy is never without green foliage. | I10: Af | J10: Tropical rain forest | K10: 2500 | L10: 26 | M10: Brazil | N10: -1.7185 | O10: -51.4583 | P10: 48.4 | Q10: 0 | Z10: 2005
A11: BR-CMT | B11: Capuaba farm Mato Grosso | C11: Mark Johnson (mark.johnson@ubc.ca) | D11: Legacy | E11: No | F11: No | G11: CRO | H11: Croplands: Lands covered with temporary crops followed by harvest and a bare soil period (e.g., single and multiple cropping systems). Note that perennial woody crops will be classified as the appropriate forest or shrub land cover type. | I11: Aw | J11: Tropical savanna | K11: 1566 | L11: 26.8 | M11: Brazil | N11: -13.2875 | O11: -56.0882 | P11: 427 | Q11: 0 | Z11: 2015 | AA11: 2019
A12: BR-CST | B12: Caatinga Serra Talhada | C12: Antonio Antonino (acdantonino@gmail.com) | D12: CC-BY-4.0 | E12: Yes | F12: Yes | G12: DNF | H12: Deciduous Needleleaf Forests: Lands dominated by woody vegetation with a percent cover >60% and height exceeding 2 meters. Consists of seasonal needleleaf tree communities with an annual cycle of leaf-on and leaf-off periods. | I12: Bsh | J12: Steppe: very cold winter | K12: 642 | L12: 25.2 | M12: Brazil | N12: -7.9682 | O12: -38.3842 | P12: 468 | Q12: 2 | R12: 2014 | S12: 2015 | T12: 2014, 2015 | U12: https://doi.org/10.17190/AMF/1562386 | V12: 2014 | W12: 2015 | X12: 2014, 2015 | Y12: https://doi.org/10.17190/AMF/1902820 | Z12: 2014 | AB12: APAR, CO2, FC, FETCH_90, GPP, H, H2O, H_SSITC_TEST, LE, LE_SSITC_TEST, MO_LENGTH, NEE, NETRAD, P, PA, RH, SC, SH, SLE, SWC, SW_IN, TA, TAU, TAU_SSITC_TEST, TS, T_SONIC, USTAR, VPD, WD, WS, WS_MAX, ZL
A13: BR-Cui | B13: Micrometeorological studies project in Amazonian mangroves | C13: Isabel Vitorino (vitorino@ufpa.br) | D13: Legacy | E13: No | F13: No | G13: WET | H13: Permanent Wetlands: Lands with a permanent mixture of water and herbaceous or woody vegetation that cover extensive areas. The vegetation can be present in either salt, brackish, or fresh water | I13: Am | J13: Tropical monsoon | K13: 457.2 | L13: 26.4 | M13: Brazil | N13: -0.6661 | O13: -47.2833 | P13: 21 | Q13: 0 | Z13: 2015
A14: BR-CUP | B14: Cupari Tapajos National Forest | C14: Scott Saleska (saleska@arizona.edu) | D14: CC-BY-4.0 | E14: No | F14: No | G14: DBF | H14: Deciduous Broadleaf Forests: Lands dominated by woody vegetation with a percent cover >60% and height exceeding 2 meters. Consists of broadleaf tree communities with an annual cycle of leaf-on and leaf-off periods. | I14: Af | J14: Tropical rain forest | K14: 1900 | L14: 25 | M14: Brazil | N14: -3.7874 | O14: -55.3664 | P14: 15 | Q14: 0 | Z14: 2024
A15: BR-IAB | B15: Instituto Arruda Botelho - Wooded Cerrado and Mixed Agriculture | C15: Edson Wendland (ew@sc.usp.br) | D15: Legacy | E15: No | F15: No | G15: WSA | H15: Woody Savannas: Lands with herbaceous and other understory systems, and with forest canopy cover between 30-60%. The forest cover height exceeds 2 meters. | I15: Cwa | J15: Humid Subtropical: dry winter, hot summer | K15: 1486 | L15: 21.6 | M15: Brazil | N15: -22.171 | O15: -47.871 | P15: 763 | Q15: 0 | Z15: 2018 | AA15: 2021
A16: BR-Ji1 | B16: Fazenda Nossa Senhora (FNS) | C16: Alessandro Araujo (alessandro.araujo@embrapa.br) | D16: CC-BY-4.0 | E16: No | F16: No | G16: GRA | H16: Grasslands: Lands with herbaceous types of cover. Tree and shrub cover is less than 10%. Permanent wetlands lands with a permanent mixture of water and herbaceous or woody vegetation. The vegetation can be present in either salt, brackish, or fresh water. | I16: Af | J16: Tropical rain forest | M16: Brazil | N16: -10.7618 | O16: -62.3572 | P16: 260 | Q16: 0 | Z16: 1999 | AA16: 2010
A17: BR-Ji3 | B17: Ji-Paraná/RO - Reserva Biológica do Jaru (RBJ) | C17: Alessandro Araujo (alessandro.araujo@embrapa.br) | D17: CC-BY-4.0 | E17: No | F17: No | G17: EBF | H17: Evergreen Broadleaf Forests: Lands dominated by woody vegetation with a percent cover >60% and height exceeding 2 meters. Almost all trees and shrubs remain green year round. Canopy is never without green foliage. | I17: Am | J17: Tropical monsoon | L17: 21 | M17: Brazil | N17: -10.1866 | O17: -61.8725 | P17: 160 | Q17: 0 | Z17: 1999
A18: BR-Ma2 | B18: Manaus - ZF2 K34 | C18: Alessandro Araujo (alessandro.araujo@gmail.com) | D18: CC-BY-4.0 | E18: No | F18: No | G18: EBF | H18: Evergreen Broadleaf Forests: Lands dominated by woody vegetation with a percent cover >60% and height exceeding 2 meters. Almost all trees and shrubs remain green year round. Canopy is never without green foliage. | I18: Af | J18: Tropical rain forest | K18: 2252 | L18: 26.68 | M18: Brazil | N18: -2.6091 | O18: -60.2093 | P18: 130 | Q18: 0 | Z18: 1999
A19: BR-Ma3 | B19: ZF3, Colosso farm | C19: Alessandro Araujo (alessandro.araujo@embrapa.br) | D19: CC-BY-4.0 | E19: No | F19: No | G19: CVM | H19: Cropland/Natural Vegetation Mosaics: Lands with a mosaic of croplands, forest, shrublands, and grasslands in which no one component comprises more than 60% of the landscape | I19: Af | J19: Tropical rain forest | K19: 2792 | L19: 29 | M19: Brazil | N19: -2.3907 | O19: -59.8835 | P19: 147 | Q19: 0 | Z19: 2008 | AA19: 2018
A20: BR-Moj | B20: Moju/PA, Commercial oil palm plantation | C20: Alessandro Araujo (alessandro.araujo@embrapa.br) | D20: CC-BY-4.0 | E20: No | F20: No | G20: CVM | H20: Cropland/Natural Vegetation Mosaics: Lands with a mosaic of croplands, forest, shrublands, and grasslands in which no one component comprises more than 60% of the landscape | I20: Af | J20: Tropical rain forest | K20: 2500 | L20: 25.5 | M20: Brazil | N20: -1.9787 | O20: -48.6147 | P20: 26 | Q20: 0 | Z20: 2015 | AA20: 2022
A21: BR-Npw | B21: Northern Pantanal Wetland | C21: Mark Johnson (mark.johnson@ubc.ca) | D21: CC-BY-4.0 | E21: Yes | F21: Yes | G21: WSA | H21: Woody Savannas: Lands with herbaceous and other understory systems, and with forest canopy cover between 30-60%. The forest cover height exceeds 2 meters. | I21: Aw | J21: Tropical savanna | K21: 1486 | L21: 24.9 | M21: Brazil | N21: -16.498 | O21: -56.412 | P21: 120 | Q21: 5 | R21: 2013 | S21: 2017 | T21: 2013, 2014, 2015, 2016, 2017 | U21: https://doi.org/10.17190/AMF/1579716 | V21: 2013 | W21: 2017 | X21: 2013, 2014, 2015, 2016, 2017 | Y21: https://doi.org/10.17190/AMF/1881563 | Z21: 2013 | AB21: CH4, CO2, FC, FCH4, G, H, LE, LW_IN, LW_OUT, NETRAD, P, PA, PPFD_IN, PPFD_OUT, RH, SW_IN, SW_OUT, TA, TS, T_SONIC, USTAR, WD, WS, WTD
A22: BR-PRS | B22: Paraíso do Sul | C22: Débora Roberti (debora@ufsm.br) | D22: Legacy | E22: No | F22: No | G22: CRO | H22: Croplands: Lands covered with temporary crops followed by harvest and a bare soil period (e.g., single and multiple cropping systems). Note that perennial woody crops will be classified as the appropriate forest or shrub land cover type. | I22: Cfa | J22: Humid Subtropical: mild with no dry season, hot summer | K22: 1500 | L22: 21 | M22: Brazil | N22: -29.744 | O22: -53.1503 | Q22: 0 | Z22: 2003 | AA22: 2004
A23: BR-Sa1 | B23: Santarem-Km67-Primary Forest | C23: Scott Saleska (saleska@email.arizona.edu) | D23: CC-BY-4.0 | E23: Yes | F23: No | G23: EBF | H23: Evergreen Broadleaf Forests: Lands dominated by woody vegetation with a percent cover >60% and height exceeding 2 meters. Almost all trees and shrubs remain green year round. Canopy is never without green foliage. | I23: Am | J23: Tropical monsoon | K23: 2074.79 | L23: 26.13 | M23: Brazil | N23: -2.8567 | O23: -54.9589 | P23: 88 | Q23: 10 | R23: 2002 | S23: 2011 | T23: 2002, 2003, 2004, 2005, 2006, 2007, 2008, 2009, 2010, 2011 | U23: https://doi.org/10.17190/AMF/1245994 | Z23: 2002 | AB23: CO2, FC, H, H2O, LE, NEE, NETRAD, PA, PPFD_IN, RECO, RH, SC, TA, USTAR, VPD, WD, WS
A24: BR-Sa3 | B24: Santarem-Km83-Logged Forest | C24: Mike Goulden (mgoulden@uci.edu) | D24: CC-BY-4.0 | E24: Yes | F24: No | G24: EBF | H24: Evergreen Broadleaf Forests: Lands dominated by woody vegetation with a percent cover >60% and height exceeding 2 meters. Almost all trees and shrubs remain green year round. Canopy is never without green foliage. | I24: Am | J24: Tropical monsoon | K24: 2043.77 | L24: 26.12 | M24: Brazil | N24: -3.018 | O24: -54.9714 | P24: 100 | Q24: 5 | R24: 2000 | S24: 2004 | T24: 2000, 2001, 2002, 2003, 2004 | U24: https://doi.org/10.17190/AMF/1245995 | Z24: 2000 | AA24: 2003 | AB24: CO2, FC, G, H, H2O, LE, LW_IN, LW_OUT, NEE, NETRAD, P, PA, PPFD_IN, PPFD_OUT, RECO, RH, SC, SWC, SW_IN, SW_OUT, TA, TS, USTAR, VPD, WD, WS
A25: BR-SGC | B25: São Gabriel da Cachoeira (Balaio Indigenous Reserve, Pico da Neblina National Park) | C25: Alessandro Araujo (alessandro.araujo@embrapa.br) | D25: CC-BY-4.0 | E25: No | F25: No | G25: EBF | H25: Evergreen Broadleaf Forests: Lands dominated by woody vegetation with a percent cover >60% and height exceeding 2 meters. Almost all trees and shrubs remain green year round. Canopy is never without green foliage. | I25: Af | J25: Tropical rain forest | K25: 3000 | L25: 27 | M25: Brazil | N25: 0.2101 | O25: -66.7529 | P25: 100 | Q25: 0 | Z25: 2004 | AA25: 2010
A26: BR-SP1 | B26: Southern Pantanal Wetland | C26: Thiago Rangel Rodrigues (thiago.r.rodrigues@ufms.br) | D26: Legacy | E26: No | F26: No | G26: WSA | H26: Woody Savannas: Lands with herbaceous and other understory systems, and with forest canopy cover between 30-60%. The forest cover height exceeds 2 meters. | I26: Aw | J26: Tropical savanna | K26: 850 | L26: 25 | M26: Brazil | N26: -19.565 | O26: -57.018 | P26: 90 | Q26: 0 | Z26: 2023
A27: CA-AF1 | B27: Acadia Research Forest | C27: Manuel Helbig (manuel.helbig@dal.ca) | D27: CC-BY-4.0 | E27: Yes | F27: No | G27: MF | H27: Mixed Forests: Lands dominated by trees with a percent cover >60% and height exceeding 2 meters. Consists of tree communities with interspersed mixtures or mosaics of the other four forest types. None of the forest types exceeds 60% of landscape. | I27: Dfb | J27: Warm Summer Continental: significant precipitation in all seasons | K27: 1078 | L27: 5.6 | M27: Canada | N27: 46.0092 | O27: -66.3627 | P27: 78 | Q27: 2 | R27: 2023 | S27: 2024 | T27: 2023, 2024 | U27: https://doi.org/10.17190/AMF/2479623 | Z27: 2023 | AB27: ALB, CO2, CO2_MIXING_RATIO, CO2_SIGMA, D_SNOW, FC, FC_SSITC_TEST, FH2O, H, H2O, H2O_MIXING_RATIO, H2O_SIGMA, H_SSITC_TEST, LE, LE_SSITC_TEST, LW_IN, LW_OUT, MO_LENGTH, PA, P_RAIN, RH, SC, SG, SH, SLE, SW_BC_IN, SWC, SW_DIF, SW_DIR, SW_IN, SW_OUT, SWP, TA, TAU, T_CANOPY, TS, T_SONIC, U_SIGMA, USTAR, VPD, V_SIGMA, WD, WS, W_SIGMA, WS_MAX, ZL
A28: CA-ARB | B28: Attawapiskat River Bog | C28: Elyn Humphreys (elynhumphreys@cunet.carleton.ca) | D28: CC-BY-4.0 | E28: Yes | F28: Yes | G28: WET | H28: Permanent Wetlands: Lands with a permanent mixture of water and herbaceous or woody vegetation that cover extensive areas. The vegetation can be present in either salt, brackish, or fresh water | I28: Dfb | J28: Warm Summer Continental: significant precipitation in all seasons | K28: 700 | L28: -1.3 | M28: Canada | N28: 52.695 | O28: -83.9452 | P28: 90 | Q28: 5 | R28: 2011 | S28: 2015 | T28: 2011, 2012, 2013, 2014, 2015 | U28: https://doi.org/10.17190/AMF/1480319 | V28: 2011 | W28: 2015 | X28: 2011, 2012, 2013, 2014, 2015 | Y28: https://doi.org/10.17190/AMF/1902821 | Z28: 2010 | AB28: ALB, CO2, D_SNOW, FC, G, H, LE, LW_IN, LW_OUT, MO_LENGTH, P, PA, RH, SWC, SW_IN, SW_OUT, TA, TAU, TS, T_SONIC, T_SONIC_SIGMA, U_SIGMA, USTAR, VPD, V_SIGMA, WD, WS, W_SIGMA, WTD, ZL
A29: CA-ARF | B29: Attawapiskat River Fen | C29: Elyn Humphreys (elynhumphreys@cunet.carleton.ca) | D29: CC-BY-4.0 | E29: Yes | F29: Yes | G29: WET | H29: Permanent Wetlands: Lands with a permanent mixture of water and herbaceous or woody vegetation that cover extensive areas. The vegetation can be present in either salt, brackish, or fresh water | I29: Dfb | J29: Warm Summer Continental: significant precipitation in all seasons | K29: 700 | L29: -1.3 | M29: Canada | N29: 52.7008 | O29: -83.955 | P29: 88 | Q29: 5 | R29: 2011 | S29: 2015 | T29: 2011, 2012, 2013, 2014, 2015 | U29: https://doi.org/10.17190/AMF/1480318 | V29: 2011 | W29: 2015 | X29: 2011, 2012, 2013, 2014, 2015 | Y29: https://doi.org/10.17190/AMF/1902822 | Z29: 2010 | AB29: ALB, CO2, D_SNOW, FC, G, H, LE, LW_IN, LW_OUT, MO_LENGTH, P, PA, RH, SWC, SW_IN, SW_OUT, TA, TAU, TS, T_SONIC, T_SONIC_SIGMA, U_SIGMA, USTAR, VPD, V_SIGMA, WD, WS, W_SIGMA, WTD, ZL
A30: CA-BCW | B30: Big Creek Watershed | C30: Carlos Barreto (carlos.barreto@ontario.ca) | D30: CC-BY-4.0 | E30: No | F30: No | G30: WET | H30: Permanent Wetlands: Lands with a permanent mixture of water and herbaceous or woody vegetation that cover extensive areas. The vegetation can be present in either salt, brackish, or fresh water | I30: Dfb | J30: Warm Summer Continental: significant precipitation in all seasons | K30: 1009.8 | L30: 7.8 | M30: Canada | N30: 42.6206 | O30: -80.5516 | P30: 201 | Q30: 0 | Z30: 2023
A31: CA-BOU | B31: Bouleau Peatland | C31: Michelle Garneau (garneau.michelle@uqam.ca) | D31: CC-BY-4.0 | E31: Yes | F31: Yes | G31: WET | H31: Permanent Wetlands: Lands with a permanent mixture of water and herbaceous or woody vegetation that cover extensive areas. The vegetation can be present in either salt, brackish, or fresh water | I31: Cwc | J31: Temperate Highland: dry winter, cool summer | K31: 1011 | L31: 1.5 | M31: Canada | N31: 50.5244 | O31: -63.2064 | P31: 108 | Q31: 3 | R31: 2018 | S31: 2020 | T31: 2018, 2019, 2020 | U31: https://doi.org/10.17190/AMF/1987599 | V31: 2018 | W31: 2020 | X31: 2018, 2019, 2020 | Y31: https://doi.org/10.17190/AMF/2469435 | Z31: 2018 | AA31: 2020 | AB31: ALB, CH4, CO2, CO2_MIXING_RATIO, FC, FCH4, FCH4_SSITC_TEST, FC_SSITC_TEST, FETCH_70, FETCH_90, FETCH_MAX, G, GPP, H, H2O, H2O_MIXING_RATIO, H_SSITC_TEST, LE, LE_SSITC_TEST, LW_IN, LW_OUT, MO_LENGTH, NEE, PA, PPFD_IN, P_RAIN, RECO, RH, SW_IN, SW_OUT, TA, TAU, TAU_SSITC_TEST, TS, T_SONIC, USTAR, VPD, WD, WS, WS_MAX, WTD, ZL
A32: CA-Ca1 | B32: British Columbia - 1949 Douglas-fir stand | C32: T. Andrew Black (andrew.black@ubc.ca) | D32: CC-BY-4.0 | E32: Yes | F32: Yes | G32: ENF | H32: Evergreen Needleleaf Forests: Lands dominated by woody vegetation with a percent cover >60% and height exceeding 2 meters. Almost all trees remain green all year. Canopy is never without green foliage. | I32: Cfb | J32: Marine West Coast: mild with no dry season, warm summer | K32: 1369 | L32: 9.93 | M32: Canada | N32: 49.8673 | O32: -125.3336 | P32: 300 | Q32: 15 | R32: 1996 | S32: 2010 | T32: 1996, 1997, 1998, 1999, 2000, 2001, 2002, 2003, 2004, 2005, 2006, 2007, 2008, 2009, 2010 | U32: https://doi.org/10.17190/AMF/1480300 | V32: 1996 | W32: 2010 | X32: 1996, 1997, 1998, 1999, 2000, 2001, 2002, 2003, 2004, 2005, 2006, 2007, 2008, 2009, 2010 | Y32: https://doi.org/10.17190/AMF/2007163 | Z32: 1997 | AB32: CO2, FC, G, GPP, H, H2O, LE, LW_IN, LW_OUT, NEE, NETRAD, PA, PPFD_BC_IN, PPFD_DIF, PPFD_IN, PPFD_OUT, P_RAIN, RECO, RH, SB, SC, SH, SLE, SWC, SW_IN, SW_OUT, TA, T_BOLE, TS, T_SONIC, USTAR, WD, WS
A33: CA-Ca2 | B33: British Columbia - Clearcut Douglas-fir stand (harvested winter 1999/2000) | C33: T. Andrew Black (andrew.black@ubc.ca) | D33: CC-BY-4.0 | E33: Yes | F33: Yes | G33: ENF | H33: Evergreen Needleleaf Forests: Lands dominated by woody vegetation with a percent cover >60% and height exceeding 2 meters. Almost all trees remain green all year. Canopy is never without green foliage. | I33: Cfb | J33: Marine West Coast: mild with no dry season, warm summer | K33: 1474 | L33: 9.86 | M33: Canada | N33: 49.8705 | O33: -125.2909 | P33: 300 | Q33: 12 | R33: 1999 | S33: 2010 | T33: 1999, 2000, 2001, 2002, 2003, 2004, 2005, 2006, 2007, 2008, 2009, 2010 | U33: https://doi.org/10.17190/AMF/1480301 | V33: 1999 | W33: 2010 | X33: 1999, 2000, 2001, 2002, 2003, 2004, 2005, 2006, 2007, 2008, 2009, 2010 | Y33: https://doi.org/10.17190/AMF/2007164 | Z33: 2000 | AB33: CO2, FC, G, GPP, H, H2O, LE, NEE, NETRAD, PA, PPFD_IN, PPFD_OUT, P_RAIN, RECO, RH, SB, SC, SH, SLE, SWC, SW_IN, SW_OUT, TA, T_BOLE, TS, USTAR, WD, WS
A34: CA-Ca3 | B34: British Columbia - Pole sapling Douglas-fir stand | C34: T. Andrew Black (andrew.black@ubc.ca) | D34: CC-BY-4.0 | E34: Yes | F34: No | G34: ENF | H34: Evergreen Needleleaf Forests: Lands dominated by woody vegetation with a percent cover >60% and height exceeding 2 meters. Almost all trees remain green all year. Canopy is never without green foliage. | I34: Cfb | J34: Marine West Coast: mild with no dry season, warm summer | K34: 1676 | L34: 9.94 | M34: Canada | N34: 49.5346 | O34: -124.9004 | Q34: 22 | R34: 2001 | S34: 2022 | T34: 2001, 2002, 2003, 2004, 2005, 2006, 2007, 2008, 2009, 2010, 2011, 2012, 2013, 2014, 2015, 2016, 2017, 2018, 2019, 2020, 2021, 2022 | U34: https://doi.org/10.17190/AMF/1480302 | Z34: 2001 | AB34: CO2, FC, G, GPP, H, H2O, LE, LW_IN, LW_OUT, NEE, NETRAD, PA, PPFD_DIF, PPFD_IN, PPFD_OUT, P_RAIN, RECO, RH, SB, SC, SG, SH, SLE, SWC, SW_IN, SW_OUT, TA, T_BOLE, TS, T_SONIC, T_SONIC_SIGMA, U_SIGMA, USTAR, VPD, V_SIGMA, WD, WS, W_SIGMA
A35: CA-Cbo | B35: Ontario - Mixed Deciduous, Borden Forest Site | C35: Ralf Staebler (Ralf.Staebler@ec.gc.ca) | D35: CC-BY-4.0 | E35: Yes | F35: Yes | G35: DBF | H35: Deciduous Broadleaf Forests: Lands dominated by woody vegetation with a percent cover >60% and height exceeding 2 meters. Consists of broadleaf tree communities with an annual cycle of leaf-on and leaf-off periods. | I35: Dfb | J35: Warm Summer Continental: significant precipitation in all seasons | K35: 876.34 | L35: 6.66 | M35: Canada | N35: 44.3167 | O35: -79.9333 | P35: 120 | Q35: 27 | R35: 1994 | S35: 2020 | T35: 1994, 1995, 1996, 1997, 1998, 1999, 2000, 2001, 2002, 2003, 2004, 2005, 2006, 2007, 2008, 2009, 2010, 2011, 2012, 2013, 2014, 2015, 2016, 2017, 2018, 2019, 2020 | U35: https://doi.org/10.17190/AMF/1498755 | V35: 1994 | W35: 2020 | X35: 1994, 1995, 1996, 1997, 1998, 1999, 2000, 2001, 2002, 2003, 2004, 2005, 2006, 2007, 2008, 2009, 2010, 2011, 2012, 2013, 2014, 2015, 2016, 2017, 2018, 2019, 2020 | Y35: https://doi.org/10.17190/AMF/1854365 | Z35: 1995 | AB35: CO2, CO2_SIGMA, FC, FO3, G, H, H2O, LE, LEAF_WET, LW_IN, LW_OUT, NEE, NETRAD, O3, PA, PPFD_IN, PPFD_OUT, RH, SC, SO2, SWC, SW_IN, SW_OUT, TA, T_BOLE, TS, T_SONIC, USTAR, WD, WS, W_SIGMA
A36: CA-CF1 | B36: Churchill Fen Site 1 | C36: Tim Papakyriakou (Tim.papakyriakou@umanitoba.ca) | D36: CC-BY-4.0 | E36: Yes | F36: Yes | G36: WET | H36: Permanent Wetlands: Lands with a permanent mixture of water and herbaceous or woody vegetation that cover extensive areas. The vegetation can be present in either salt, brackish, or fresh water | I36: Dfc | J36: Subarctic: severe winter, no dry season, cool summer | K36: 452 | L36: -6.5 | M36: Canada | N36: 58.6658 | O36: -93.83 | P36: 16.5 | Q36: 2 | R36: 2007 | S36: 2008 | T36: 2007, 2008 | U36: https://doi.org/10.17190/AMF/1660336 | V36: 2007 | W36: 2008 | X36: 2007, 2008 | Y36: https://doi.org/10.17190/AMF/2229375 | Z36: 2007 | AA36: 2008 | AB36: CO2, FC, H, H2O, LE, NETRAD, PA, PPFD_IN, P_RAIN, RH, SW_IN, TA, TS, USTAR, WD, WS
A37: CA-CF2 | B37: Churchill Fen Site 2 | C37: Mario Tenuta (Mario.Tenuta@umanitoba.ca) | D37: CC-BY-4.0 | E37: Yes | F37: No | G37: WET | H37: Permanent Wetlands: Lands with a permanent mixture of water and herbaceous or woody vegetation that cover extensive areas. The vegetation can be present in either salt, brackish, or fresh water | I37: Dfc | J37: Subarctic: severe winter, no dry season, cool summer | K37: 452 | L37: -6.5 | M37: Canada | N37: 58.6658 | O37: -93.83 | P37: 16.5 | Q37: 4 | R37: 2008 | S37: 2011 | T37: 2008, 2009, 2010, 2011 | U37: https://doi.org/10.17190/AMF/1634879 | Z37: 2008 | AA37: 2011 | AB37: CH4, CO2, FC, FCH4, H, H2O, LE, NETRAD, PA, PPFD_IN, P_RAIN, RH, SW_IN, TA, TS, USTAR, WD, WS
A38: CA-CF3 | B38: Churchill Fen Site 3 | C38: Susan Natali (snatali@woodwellclimate.org) | D38: CC-BY-4.0 | E38: Yes | F38: No | G38: WET | H38: Permanent Wetlands: Lands with a permanent mixture of water and herbaceous or woody vegetation that cover extensive areas. The vegetation can be present in either salt, brackish, or fresh water | I38: Dfc | J38: Subarctic: severe winter, no dry season, cool summer | M38: Canada | N38: 58.6658 | O38: -93.8304 | P38: 25 | Q38: 2 | R38: 2022 | S38: 2023 | T38: 2022, 2023 | U38: https://doi.org/10.17190/AMF/2335573 | Z38: 2022 | AB38: ALB, CH4, CH4_MIXING_RATIO, CO2, CO2_MIXING_RATIO, D_SNOW, FC, FCH4, FCH4_SSITC_TEST, FC_SSITC_TEST, FH2O, G, GPP, H, H2O, H_SSITC_TEST, LE, LE_SSITC_TEST, LW_IN, LW_OUT, MO_LENGTH, NETRAD, P, PA, PPFD_IN, PPFD_OUT, RECO, RH, SWC, SW_IN, SW_OUT, TA, TAU, TAU_SSITC_TEST, TS, T_SONIC, U_SIGMA, USTAR, VPD, V_SIGMA, WD, WS, W_SIGMA, WS_MAX, ZL
A39: CA-Cha | B39: New Brunswick - Charlie Lake site 01 (immature balsam fir forest to be thinned in year 3) | C39: Charles Bourque (cbourque@unb.ca) | D39: CC-BY-4.0 | E39: Yes | F39: No | G39: MF | H39: Mixed Forests: Lands dominated by trees with a percent cover >60% and height exceeding 2 meters. Consists of tree communities with interspersed mixtures or mosaics of the other four forest types. None of the forest types exceeds 60% of landscape. | I39: Dfb | J39: Warm Summer Continental: significant precipitation in all seasons | K39: 971.68 | L39: 3.46 | M39: Canada | N39: 45.8847 | O39: -67.3569 | P39: 341 | Q39: 2 | R39: 2004 | S39: 2005 | T39: 2004, 2005 | U39: https://doi.org/10.17190/AMF/1436317 | Z39: 2004 | AA39: 2005 | AB39: FC, G, H, LE, NETRAD, PA, PPFD_IN, P_RAIN, RH, SWC, SW_IN, SW_OUT, TA, TS, USTAR, WD, WS
A40: CA-CQ1 | B40: Québec. Carbonique1 - Lac Saint-Pierre Disturbed Marsh | C40: Sara Knox (sara.knox@mcgill.ca) | D40: CC-BY-4.0 | E40: No | F40: No | G40: CRO | H40: Croplands: Lands covered with temporary crops followed by harvest and a bare soil period (e.g., single and multiple cropping systems). Note that perennial woody crops will be classified as the appropriate forest or shrub land cover type. | I40: Dfb | J40: Warm Summer Continental: significant precipitation in all seasons | K40: 872.8 | L40: 5.9 | M40: Canada | N40: 46.1645 | O40: -72.685 | P40: 6 | Q40: 0 | Z40: 2024
...

Sheet OzFlux
A1: Name [Fluxnet] | B1: Landcover | C1: annual Rainfall | D1: Temp range °C | E1: Location | F1: Group | G1: Status | H1: Contact
E2: [Lat, Long] | I2: Last access | J2: Status | K2: Latest year available
A3: Adelaide River | E3: Savanna dominated by Eucalyptus tectifica and Planchonia careya.
A4: [AU-Adr] | E4: [-13.0769, 131.1178] | I4: https://data.ozflux.org.au/portal/pub/viewColDetails.jspx?collection.id=1882701&collection.owner.id=304&viewType=anonymous | J4: L3 | K4: 2009
A5: Alice Springs Mulga | B5: Semi-arid mulga (Acacia aneura) ecosystem | C5: 306mm | D5: =-4 - 46 -> -50 | E5: Pine Hill cattle station, near Alice Springs, Northern Territory | F5: James Cook University | G5: Running since September 2010 | H5: Jamie Cleverly | I5: 45600 | J5: L3,L6 | K5: 2023
A6: [AU-ASM] | E6: [-22.2828, 133.2493] | I6: https://data.ozflux.org.au/portal/pub/viewColDetails.jspx?collection.id=152&collection.owner.id=101&viewType=anonymous
A7: Alpine Peatland | B7: Alpine Sphagnum peatland | C7: 1274mm | D7: =-3 - 17 -> -20 | E7: Bogong High Plains near Falls Creek in the Victorian Alpine National Parks | F7: Royal Melbourne Institute of Technology | G7: Running since April 2017 | H7: Samantha Grover | I7: 45600 | J7: L3 | K7: 2022
A8: [AU-APL] | E8: [-36.8607, 147.3208] | I8: https://data.ozflux.org.au/portal/pub/viewColDetails.jspx?collection.id=1884200&collection.owner.id=2024253&viewType=anonymous
A9: Boyagin | B9: Wandoo woodland (surrounding area dominated by broadacre farming) | C9: 445mm | D9: 11841 | E9: Boyagin Nature Reserve 12km W of Pingelly, Western Australia | F9: University of Western Australia | G9: Running since September 2017 | H9: Jason Beringer | I9: 45600 | J9: L3 | K9: 2024
A10: [AU-Boy] | E10: [-32.4771, 116.9386] | I10: https://data.ozflux.org.au/portal/pub/viewColDetails.jspx?collection.id=1883606&collection.owner.id=304&viewType=anonymous
A11: Calperum | B11: Recovering Mallee woodland | C11: 240mm | D11: 16772 | E11: Calperum Station, 25km NW of Renmark, South Australia | F11: University of Adelaide | G11: Running since July 2010 | H11: Wayne Meyer | I11: 45600 | J11: L3 | K11: 2024
A12: [AU-Cpr] | E12: [-34.0027, 140.5877] | I12: https://data.ozflux.org.au/portal/pub/viewColDetails.jspx?collection.id=1882712&collection.owner.id=703&viewType=anonymous
A13: Cow Bay | B13: Complex mesophyll vine forest | C13: 4000mm | D13: 14550 | E13: Daintree Discovery Centre at Cow Bay, 100km from Cairns, Qld | F13: James Cook University | G13: Running since December 2008 | H13: Michael Liddell | I13: 45600 | J13: L3 | K13: 2024
A14: [AU-Cow] | E14: [-16.238189, 145.427150] | F14: (Cairns) | I14: https://data.ozflux.org.au/portal/pub/viewColDetails.jspx?collection.id=1882720&collection.owner.id=100&viewType=anonymous
F16: Daintree Discovery Centre
A17: Cumberland Plain | B17: Dry sclerophyll | C17: 800mm | D17: 47178 | E17: Hawkesbury Valley in central New South Wales | F17: Western Sydney University | G17: Running since September 2012 | H17: Elise Pendall | I17: 45600 | J17: L3,L6 | K17: 2024
A18: [AU-Cum] | E18: [-33.6152, 150.7236] | I18: https://data.ozflux.org.au/portal/pub/viewColDetails.jspx?collection.id=1883300&collection.owner.id=2021853&viewType=anonymous
A19: Daly River Uncleared | B19: Woodland savanna | C19: 1170mm | D19: 13850 | E19: Douglas River Daly River Esplanade Conservation area, approx. 60km south west of Pine Creek, Northern Territory | F19: University of Western Australia | G19: Running since February 2007 | H19: Jason Beringer, | I19: 45600 | J19: L1,L2,L3 | K19: 2024
A20: [AU-DaS] | E20: [-14.1592, 131.3881] | H20: Lindsay Hutley | I20: https://data.ozflux.org.au/portal/pub/viewColDetails.jspx?collection.id=1882715&collection.owner.id=304&viewType=anonymous
F21: Charles Darwin University
A22: Dry River | B22: Open forest savanna | C22: 895mm | D22: 14 - 37 | E22: approx. 89km south of Katherine, Northern Territory | F22: University of Western Australia | G22: Running since September 2008 | H22: Jason Beringer, | I22: 45600 | J22: L3 | K22: 2024
A23: [AU-Dry] | E23: [-15.2588, 132.3706] | H23: Lindsay Hutley | I23: https://data.ozflux.org.au/portal/pub/viewColDetails.jspx?collection.id=1882702&collection.owner.id=304&viewType=anonymous
F24: Charles Darwin University
A25: French Island | B25: Saltmarsh | C25: 540mm | D25: 14642 | E25: South west tip of Franch Island, Victoria | F25: Monash University | G25: Running since March 2019 | H25: Matthew Peck,
E26: [-38.3879, 145.2783] | H26: Leigh Burgess,
H27: Ruth Reef
A28: Gatum Pasture | B28: Grazing pasture (predominantly Phalaris aquatica L. and Trifolium subteraneum L.) | C28: 736mm | D28: =-1 - 40 -> -41 | E28: South western Victoria, approximately 260km west of Melbourne | F28: Monash University | G28: Running since January 2015 | H28: Edoardo Daly, | I28: 45600 | J28: L3 | K28: 2021
E29: [-37.3903, 141.9716] | H29: Ian McHugh | I29: https://data.ozflux.org.au/portal/pub/viewColDetails.jspx?collection.id=1884201&collection.owner.id=2024206&viewType=anonymous
F30: La Trobe University
A31: Gingin | B31: Coastal heath Banksia woodland | C31: 641mm | D31: 19 - 30 | E31: Swan Coastal Plain 70km north of Perth, Western Australia | F31: Edith Cowan University | G31: Running since June 2011 | H31: Richard Silberstein
A32: [AU-Gin] | E32: [-31.3764, 115.7139]
A33: Great Western Woodlands | B33: Temperate woodland, shrubland and mallee | C33: 240mm | D33: 12175 | E33: Credo Station, 110km NNW of Kalgoorlie, WA | F33: CSIRO Environment | G33: Active since December 2012 | H33: Craig Macfarlane, | I33: 45600 | J33: L1,L3 | K33: 2024
A34: [AU-GWW] | E34: [-30.1913, 120.6541] | H34: Suzanne Prober | I34: https://data.ozflux.org.au/portal/pub/viewColDetails.jspx?collection.id=750&collection.owner.id=2024852&viewType=anonymous
A35: Howard Springs | B35: Tropical savanna (wet) | C35: 1700mm | D35: 20 - 33 | E35: E of Darwin, NT | F35: University of Western Australia | G35: Running since August 2001 data available from 1997 | H35: Jason Beringer, | I35: 45600 | J35: L3 | K35: 2024
A36: [AU-How] | E36: [-12.4943, 131.1523] | H36: Lindsay Hutley | I36: https://data.ozflux.org.au/portal/pub/viewColDetails.jspx?collection.id=1882710&collection.owner.id=304&viewType=anonymous
F37: Charles Darwin University
A38: Kopuatai | B38: Raised peat bog | C38: 1262mm | E38: lower Hauraki plains of the North Island | F38: University of Waikato | G38: Running since November 2011 | H38: Dave Campbell | I38: 45600 | J38: L0 | K38: 2015
A39: [NZ-Kop] | E39: [-37.3880, 175.5540] | I39: https://data.ozflux.org.au/portal/pub/viewColDetails.jspx?collection.id=1883801&collection.owner.id=2023102&viewType=anonymous
A40: Litchfield | B40: Tropical savanna | E40: 80 km south of Darwin | F40: University of Western Australia | G40: Running since 2015 | H40: Jason Beringer, | I40: 45600 | J40: L3 | K40: 2024
A41: [AU-Lit] | E41: [-13.1790, 130.7945] | H41: Lindsay Hutley | I41: https://data.ozflux.org.au/portal/pub/viewColDetails.jspx?collection.id=1883302&collection.owner.id=304&viewType=anonymous
...

Sheet ICOS
A1: Site | B1: Period | C1: Dataset | D1: x | E1: y | F1: metadata
A2: BE-Lon | B2: 2004-2018 | C2: ICOS-Drought | D2: 4.746202 | E2: 50.551338 | F2: =_xlfn.CONCAT("https://meta.icos-cp.eu/resources/stations/ES_",A2) -> https://meta.icos-cp.eu/resources/stations/ES_BE-Lon
A3: DE-Hte | B3: 2009-2018 | C3: ICOS-Drought | D3: 12.176111 | E3: 54.210278 | F3: =_xlfn.CONCAT("https://meta.icos-cp.eu/resources/stations/ES_",A3) -> https://meta.icos-cp.eu/resources/stations/ES_DE-Hte
A4: FR-EM2 | B4: 2017-2018 | C4: ICOS-Drought | D4: 3.02065 | E4: 49.87211 | F4: =_xlfn.CONCAT("https://meta.icos-cp.eu/resources/stations/ES_",A4) -> https://meta.icos-cp.eu/resources/stations/ES_FR-EM2
A5: NL-Loo | B5: 1996-2018 | C5: ICOS-Drought | D5: 5.74355 | E5: 52.166447 | F5: =_xlfn.CONCAT("https://meta.icos-cp.eu/resources/stations/ES_",A5) -> https://meta.icos-cp.eu/resources/stations/ES_NL-Loo
A6: SE-Lnn | B6: 2014-2018 | C6: ICOS-Drought | D6: 13.10177 | E6: 58.34063 | F6: =_xlfn.CONCAT("https://meta.icos-cp.eu/resources/stations/ES_",A6) -> https://meta.icos-cp.eu/resources/stations/ES_SE-Lnn
A7: BE-Bra | B7: 1996-2020 | C7: ICOS-WW | D7: 4.520098 | E7: 51.30701 | F7: =_xlfn.CONCAT("https://meta.icos-cp.eu/resources/stations/ES_",A7) -> https://meta.icos-cp.eu/resources/stations/ES_BE-Bra
A8: BE-Dor | B8: 2011-2020 | C8: ICOS-WW | D8: 4.968113 | E8: 50.311874 | F8: =_xlfn.CONCAT("https://meta.icos-cp.eu/resources/stations/ES_",A8) -> https://meta.icos-cp.eu/resources/stations/ES_BE-Dor
A9: BE-Lcr | B9: 2019-2020 | C9: ICOS-WW | D9: 3.85043 | E9: 51.11218 | F9: =_xlfn.CONCAT("https://meta.icos-cp.eu/resources/stations/ES_",A9) -> https://meta.icos-cp.eu/resources/stations/ES_BE-Lcr
A10: BE-Lon | B10: 2004-2020 | C10: ICOS-WW | D10: 4.746202 | E10: 50.551338 | F10: =_xlfn.CONCAT("https://meta.icos-cp.eu/resources/stations/ES_",A10) -> https://meta.icos-cp.eu/resources/stations/ES_BE-Lon
A11: BE-Maa | B11: 2016-2020 | C11: ICOS-WW | D11: 5.630835 | E11: 50.980054 | F11: =_xlfn.CONCAT("https://meta.icos-cp.eu/resources/stations/ES_",A11) -> https://meta.icos-cp.eu/resources/stations/ES_BE-Maa
A12: BE-Vie | B12: 1996-2020 | C12: ICOS-WW | D12: 5.99871 | E12: 50.306918 | F12: =_xlfn.CONCAT("https://meta.icos-cp.eu/resources/stations/ES_",A12) -> https://meta.icos-cp.eu/resources/stations/ES_BE-Vie
A13: CH-Aws | B13: 2006-2020 | C13: ICOS-WW | D13: 9.790417 | E13: 46.583306 | F13: =_xlfn.CONCAT("https://meta.icos-cp.eu/resources/stations/ES_",A13) -> https://meta.icos-cp.eu/resources/stations/ES_CH-Aws
... A79: SE-Svb | B79: 2014-2020 | C79: ICOS-WW | D79: 19.776502 | E79: 64.256305 | F79: =_xlfn.CONCAT("https://meta.icos-cp.eu/resources/stations/ES_",A79) -> https://meta.icos-cp.eu/resources/stations/ES_SE-Svb

Sheet FLUXNET2015
A1: https://fluxnet.org/sites/site-list-and-pages/
A2: SITE_ID | B2: SITE_NAME | C2: FLUXNET2015 | D2: FLUXNET-CH4 | E2: LOCATION_LAT | F2: LOCATION_LONG | G2: LOCATION_ELEV | H2: IGBP | I2: MAT | J2: MAP
A3: AR-SLu | B3: San Luis | C3: CC-BY-4.0 | E3: -33.4648 | F3: -66.4598 | H3: MF | J3: 400
A4: AR-Vir | B4: Virasoro | C4: CC-BY-4.0 | E4: -28.2395 | F4: -56.1886 | H4: ENF
A5: AT-Neu | B5: Neustift | C5: CC-BY-4.0 | D5: CC-BY-4.0 | E5: 47.1167 | F5: 11.3175 | G5: 970 | H5: GRA | I5: 6.5 | J5: 852
A6: AU-ASM | B6: Alice Springs | C6: CC-BY-4.0 | E6: -22.283 | F6: 133.249 | H6: SAV
A7: AU-Ade | B7: Adelaide River | C7: CC-BY-4.0 | E7: -13.0769 | F7: 131.1178 | H7: WSA
A8: AU-Cpr | B8: Calperum | C8: CC-BY-4.0 | E8: -34.0021 | F8: 140.5891 | H8: SAV
A9: AU-Cum | B9: Cumberland Plain | C9: CC-BY-4.0 | E9: -33.6152 | F9: 150.7236 | H9: EBF
A10: AU-DaP | B10: Daly River Pasture | C10: CC-BY-4.0 | E10: -14.0633 | F10: 131.3181 | H10: GRA | I10: 27.25 | J10: 983.78
A11: AU-DaS | B11: Daly River Savanna | C11: CC-BY-4.0 | E11: -14.1593 | F11: 131.3881 | H11: SAV | I11: 27.22 | J11: 975.82
A12: AU-Dry | B12: Dry River | C12: CC-BY-4.0 | E12: -15.2588 | F12: 132.3706 | H12: SAV
A13: AU-Emr | B13: Emerald | C13: CC-BY-4.0 | E13: -23.8587 | F13: 148.4746 | H13: GRA
A14: AU-Fog | B14: Fogg Dam | C14: CC-BY-4.0 | E14: -12.5452 | F14: 131.3072 | H14: WET | I14: 27.02 | J14: 1323.69
A15: AU-GWW | B15: Great Western Woodlands, Western Australia, Australia | C15: CC-BY-4.0 | E15: -30.1913 | F15: 120.6541 | H15: SAV
A16: AU-Gin | B16: Gingin | C16: CC-BY-4.0 | E16: -31.3764 | F16: 115.7138 | H16: WSA
A17: AU-How | B17: Howard Springs | C17: CC-BY-4.0 | E17: -12.4943 | F17: 131.1523 | H17: WSA | I17: 27.01 | J17: 1449.35
A18: AU-Lox | B18: Loxton | C18: CC-BY-4.0 | E18: -34.4704 | F18: 140.6551 | H18: DBF
A19: AU-RDF | B19: Red Dirt Melon Farm, Northern Territory | C19: CC-BY-4.0 | E19: -14.5636 | F19: 132.4776 | H19: WSA
A20: AU-Rig | B20: Riggs Creek | C20: CC-BY-4.0 | E20: -36.6499 | F20: 145.5759 | H20: GRA
A21: AU-Rob | B21: Robson Creek, Queensland, Australia | C21: CC-BY-4.0 | E21: -17.1175 | F21: 145.6301 | H21: EBF
A22: AU-Stp | B22: Sturt Plains | C22: CC-BY-4.0 | E22: -17.1507 | F22: 133.3502 | H22: GRA
A23: AU-TTE | B23: Ti Tree East | C23: CC-BY-4.0 | E23: -22.287 | F23: 133.64 | H23: GRA
A24: AU-Tum | B24: Tumbarumba | C24: CC-BY-4.0 | E24: -35.6566 | F24: 148.1517 | G24: 1200 | H24: EBF | I24: 10.72 | J24: 1159.01
A25: AU-Wac | B25: Wallaby Creek | C25: CC-BY-4.0 | E25: -37.4259 | F25: 145.1878 | H25: EBF | I25: 12.76 | J25: 1105.59
A26: AU-Whr | B26: Whroo | C26: CC-BY-4.0 | E26: -36.6732 | F26: 145.0294 | H26: EBF
A27: AU-Wom | B27: Wombat | C27: CC-BY-4.0 | E27: -37.4222 | F27: 144.0944 | G27: 705 | H27: EBF
A28: AU-Ync | B28: Jaxa | C28: CC-BY-4.0 | E28: -34.9893 | F28: 146.2907 | H28: GRA
A29: BE-Bra | B29: Brasschaat | C29: CC-BY-4.0 | E29: 51.3076 | F29: 4.5198 | G29: 16 | H29: MF | I29: 9.8 | J29: 750
A30: BE-Lon | B30: Lonzee | C30: CC-BY-4.0 | E30: 50.5516 | F30: 4.7462 | G30: 167 | H30: CRO | I30: 10 | J30: 800
A31: BE-Vie | B31: Vielsalm | C31: CC-BY-4.0 | E31: 50.3049 | F31: 5.9981 | G31: 493 | H31: MF | I31: 7.8 | J31: 1062
